<!DOCTYPE html>
<html lang="en">
<head>
    <meta charset="UTF-8">
    <title>promise对象</title>
</head>
<body>
<script>
    (function () {
        /*function timeout(ms) {
            return new Promise((resolve, reject) =>{
                //setTimeout(code, milliseconds, param1, param2, ...)
                //param1, param2, ...: 可选。 传给执行函数的其他参数（IE9 及其更早版本不支持该参数）。
                setTimeout(resolve, ms, 'done');
            });
        }
        timeout(100).then((value)=>{
            console.log(value);
        })*/

        /*
         * Promise新建后立即执行，首先输出Promise。
         * 然后then方法指定的回调函数，将在当前脚本所有同步任务执行完才会执行，resolved最后输出。
         */
        /*let promise = new Promise(function (resolve,reject) {
            console.log("Promise");
            resolve();
        });
        promise.then(function () {
            console.log("resolved");
        });
        console.log("hi");*/

        /*
        p1的状态传递给p2，即p1的状态决定p2的状态。如果p1的状态是pending，那么p2的回调函数就会等待p1的状态改变；
        如果p1的状态已经是resolved或者rejected，那么p2的回调函数将会立刻执行。
        p1是一个 Promise，3 秒之后变为rejected。p2的状态在 1 秒之后改变，resolve方法返回的是p1。
        由于p2返回的是另一个 Promise，导致p2自己的状态无效了，由p1的状态决定p2的状态。
        所以，后面的then语句都变成针对后者（p1）。又过了 2 秒，p1变为rejected，导致触发catch方法指定的回调函数。*/
        /*const p1 = new Promise(function (resolve, reject) {
            setTimeout(()=> reject(new Error('fail')),3000);
        });
        const p2 = new Promise(function (resolve, reject) {
            setTimeout(()=> resolve(p1),1000);
        });
        p2.then(result => console.log(result))
            .catch(error => console.log(error));*/

        //调用resolve或reject并不会终结 Promise 的参数函数的执行。
        /*let p = new Promise((resolve, reject) => {
            resolve(1);
            console.log(2);
        });
        p.then(r => console.log(r));*/

        //Promise.prototype.finally()

        //Promise.all()
        //作为参数的Promise实例定义catch方法，那么它一旦被rejected，并不会触发Promise.all()的catch方法
        //p1会resolved，p2首先会rejected，但是p2有自己的catch方法，该方法返回的是一个新的 Promise 实例，
        //p2指向的实际上是这个实例。该实例执行完catch方法后，也会变成resolved，导致Promise.all()方法参数里面的两个实例都会resolved，
        //因此会调用then方法指定的回调函数，而不会调用catch方法指定的回调函数。
        let p1 = new Promise((resolve, reject) => {
            resolve('hello');
        }).then(result => result).catch(e => e);
        let p2 = new Promise((resolve, reject) => {
            throw new Error("报错了");
        }).then(result => result).catch(e => e);
        Promise.all([p1,p2]).then(result => console.log(result))
            .catch(e => console.log(e));

        //如果p2没有自己的catch方法，就会调用Promise.all()的catch方法。

    })();
</script>
</body>
</html>